2019-12-09 14:39:53 httpbin_validator.py [line:69] ERROR: HTTPConnectionPool(host='171.35.147.17', port=9999): Max retries exceeded with url: http://httpbin.org/get (Caused by ConnectTimeoutError(<urllib3.connection.HTTPConnection object at 0x10e679dd8>, 'Connection to 171.35.147.17 timed out. (connect timeout=10)'))
2019-12-09 14:40:03 httpbin_validator.py [line:69] ERROR: HTTPSConnectionPool(host='httpbin.org', port=443): Max retries exceeded with url: /get (Caused by ConnectTimeoutError(<urllib3.connection.VerifiedHTTPSConnection object at 0x10e697630>, 'Connection to 171.35.147.17 timed out. (connect timeout=10)'))
2019-12-09 14:41:21 httpbin_validator.py [line:69] ERROR: HTTPConnectionPool(host='49.85.179.137', port=9999): Max retries exceeded with url: http://httpbin.org/get (Caused by ProxyError('Cannot connect to proxy.', NewConnectionError('<urllib3.connection.HTTPConnection object at 0x10ee77dd8>: Failed to establish a new connection: [Errno 61] Connection refused',)))
2019-12-09 14:41:21 httpbin_validator.py [line:69] ERROR: HTTPSConnectionPool(host='httpbin.org', port=443): Max retries exceeded with url: /get (Caused by ProxyError('Cannot connect to proxy.', NewConnectionError('<urllib3.connection.VerifiedHTTPSConnection object at 0x10ee95630>: Failed to establish a new connection: [Errno 61] Connection refused',)))
